Workbook
Name base: Tabela1[#All]
Name Cabecalho: Tabela7[#All]

Sheet Apoio
B2: Lista de Despesas Possíveis | F2: Lista de Empresas | H2: Formas de Comprovante | K2: Formas de Comprovante
B3: Nível 3 | C3: Nível 2 | D3: Nível 1 | F3: Razão Social | H3: Lista de Comprovantes | K3: ID | L3: UF
B4: Recurso Inominado | C4: Recurso | D4: CUSTAS JUDICIAIS | F4: BANCO PAN S/A | H4: Guia (Boleto) | K4: 8.01
B5: Recurso - Apelação | C5: Recurso | D5: CUSTAS JUDICIAIS | F5: BM SUA CASA PROMOTORA DE VENDAS LTDA | H5: Recibo | K5: 8.02
B6: Recurso - Extraordinário | C6: Recurso | D6: CUSTAS JUDICIAIS | F6: BRAZILIAN FINANCE E REAL ESTATE S/A | H6: Nota Fiscal | K6: 8.03
B7: Recurso - Especial | C7: Recurso | D7: CUSTAS JUDICIAIS | F7: BRAZILIAN SECURITIES COMPANHIA DE SECURITIZACAO | K7: 8.04
B8: Recurso - Agravo | C8: Recurso | D8: CUSTAS JUDICIAIS | F8: PAN ADMINISTRADORA DE CONSORCIO LTDA | K8: 8.05
B9: Recurso - Mandado de Segurança | C9: Custas | D9: CUSTAS JUDICIAIS | F9: PAN ARRENDAMENTO MERCANTIL S/A | K9: 8.06
B10: Custas Iniciais (Reconvenção) | C10: Custas | D10: CUSTAS JUDICIAIS | H10: Tipos de Pagamentos | K10: 8.07
B11: Custas Finais | C11: Custas | D11: CUSTAS JUDICIAIS | H11: Tipos | K11: 8.08
B12: Guia de Ofício | D12: CUSTAS JUDICIAIS | F12: Tipodes de Natureza | H12: Fundo Fixo | K12: 8.09
B13: Taxa Judicial | D13: CUSTAS JUDICIAIS | F13: Natureza | K13: 8.10
B14: Honorários Periciais | D14: HONORÁRIOS | F14: ADMINISTRATIVO | K14: 8.11
B15: Honorários Advocatícios | D15: HONORÁRIOS | F15: CONSUMO | K15: 8.12
B16: Honorário de Conciliador | D16: HONORÁRIOS | F16: EMPRESAS | K16: 8.13
B17: Correios / Taxa de postagem | C17: Outras despesas | D17: EXTRAJUDICIAL | F17: EMPRESAS IMOBILIARIO | H17: Formas de Pagamento | K17: 8.14
B18: Despesas Cartoriais | C18: Outras despesas | D18: CUSTAS JUDICIAIS | F18: ESTRATEGICO CIVEL | H18: Lista Pagamentos | K18: 8.15
B19: Taxa de Mandato | D19: CUSTAS JUDICIAIS | F19: EXTRAORDINARIO | H19: Boleto | K19: 8.16
B20: Pesquisas | C20: Outras despesas | D20: CUSTAS JUDICIAIS | F20: IMOBILIARIO | H20: PIX | K20: 8.17
B21: Porte de remessa e retorno | D21: CUSTAS JUDICIAIS | F21: MULTA PROCON | H21: TED | K21: 8.18
B22: Desarquivamento | D22: CUSTAS JUDICIAIS | F22: PROCON | H22: DOC | K22: 8.19
B23: Transporte | D23: CUSTAS JUDICIAIS | F23: RISCO ELEVADO | K23: 8.20
B24: Condenação | D24: CONDENAÇÃO | F24: TRABALHISTA | K24: 8.21
B25: Impugnação | F25: TRIBUTARIO | K25: 8.22
K26: 8.23
K27: 8.24
K28: 8.25
K29: 8.26
K30: 8.27
K31: 8.28
K32: 8.29
K33: 8.30
B37: Lista de Produtos
B38: PRODUTO | C38: CC | D38: Produtos - Simples
B39: JURÍDICO - AUTOPAN | C39: 15600 | D39: =SUBSTITUTE(Tabela8[[#This Row],[PRODUTO]],"JURÍDICO - ","") -> AUTOPAN
B40: JURÍDICO - BALCÃO | C40: 15601 | D40: =SUBSTITUTE(Tabela8[[#This Row],[PRODUTO]],"JURÍDICO - ","") -> BALCÃO
B41: JURÍDICO - CARTÕES | C41: 15602 | D41: =SUBSTITUTE(Tabela8[[#This Row],[PRODUTO]],"JURÍDICO - ","") -> CARTÕES
B42: JURÍDICO - CDC | C42: 15603 | D42: =SUBSTITUTE(Tabela8[[#This Row],[PRODUTO]],"JURÍDICO - ","") -> CDC
B43: JURÍDICO - CONSIGNADO INSS | C43: 15604 | D43: =SUBSTITUTE(Tabela8[[#This Row],[PRODUTO]],"JURÍDICO - ","") -> CONSIGNADO INSS
B44: JURÍDICO - CONSIGNADO PÚBLICO | C44: 15605 | D44: =SUBSTITUTE(Tabela8[[#This Row],[PRODUTO]],"JURÍDICO - ","") -> CONSIGNADO PÚBLICO
...

Sheet Base
B1: | Relatório de Reembolsos - Consumo | Varejo
A2: Coluna1 | B2: ID do Caso | C2: Data da Despesa | D2: R$ Valor | E2: Nº Guia | F2: Nível 3 - Despesa | G2: Complemento | H2: Tipo de Comprovante | I2: Forma de Pagamento | J2: ID da Evidência | K2: Produto | L2: Natureza | M2: Nº Processo | N2: Autor | O2: Réu | P2: Empresa Pagadora | Q2: Observação | R2: Validação | S2: Range de Pagamento | T2: Duplicidade na solicitação | U2: Campos Não Preenchidos | V2: Centro de Custo | W2: Escritório | X2: CNPJ | Y2: Data da Solicitação | Z2: Nº Nota ou Recibo | AA2: N° planilha de pagamentos do PANJUR | AB2: Tipo
W3: DIAS COSTA ADVOGADOS ASSOCIADOS | X3: 10.999.280/0001-47
W4: DIAS COSTA ADVOGADOS ASSOCIADOS | X4: 10.999.280/0001-47
W5: DIAS COSTA ADVOGADOS ASSOCIADOS | X5: 10.999.280/0001-47
W6: DIAS COSTA ADVOGADOS ASSOCIADOS | X6: 10.999.280/0001-47
W7: DIAS COSTA ADVOGADOS ASSOCIADOS | X7: 10.999.280/0001-47
W8: DIAS COSTA ADVOGADOS ASSOCIADOS | X8: 10.999.280/0001-47
W9: DIAS COSTA ADVOGADOS ASSOCIADOS | X9: 10.999.280/0001-47
W10: DIAS COSTA ADVOGADOS ASSOCIADOS | X10: 10.999.280/0001-47
W11: DIAS COSTA ADVOGADOS ASSOCIADOS | X11: 10.999.280/0001-47
W12: DIAS COSTA ADVOGADOS ASSOCIADOS | X12: 10.999.280/0001-47
W13: DIAS COSTA ADVOGADOS ASSOCIADOS | X13: 10.999.280/0001-47
W14: DIAS COSTA ADVOGADOS ASSOCIADOS | X14: 10.999.280/0001-47
... W100: DIAS COSTA ADVOGADOS ASSOCIADOS | X100: 10.999.280/0001-47

Sheet Contábil
A1: COD / FATURA | B1: TIPO DE DESPESA | C1: EMPRESA | D1: FORNECEDOR | E1: PASTA | F1: AUTOR | G1: RÉU | H1: PROCESSO | I1: VALOR
A2: {=IFERROR(OFFSET(Tabela1[[#Headers],[Nº Nota ou Recibo]],1,0,Infos!$E$5,1),"")} | B2: {=IFERROR(_xlfn.XLOOKUP(OFFSET(Tabela1[[#Headers],[Nível 3 - Despesa]],1,0,Infos!$E$5,1),Tabela2[Nível 3],Tabela2[Nível 1]),"")} | C2: {=IFERROR(OFFSET(Tabela1[[#Headers],[Empresa Pagadora]],1,0,Infos!$E$5,1),"")} | D2: {=IFERROR(OFFSET(Tabela1[[#Headers],[Escritório]],1,0,Infos!$E$5,1),"")} | E2: {=IFERROR(OFFSET(Tabela1[[#Headers],[ID do Caso]],1,0,Infos!$E$5,1),"")} | F2: {=IFERROR(UPPER(OFFSET(Tabela1[[#Headers],[Autor]],1,0,Infos!$E$5,1)),"")} | G2: {=IFERROR(OFFSET(Tabela1[[#Headers],[Réu]],1,0,Infos!$E$5,1),"")} | H2: {=IFERROR(OFFSET(Tabela1[[#Headers],[Nº Processo]],1,0,Infos!$E$5,1),"")} | I2: {=IFERROR(OFFSET(Tabela1[[#Headers],[R$ Valor]],1,0,Infos!$E$5,1),"")}

Sheet Infos
B1: Solicitação de Reembolso - Custas
B3: Informações Gerais
B4: Cabeçaho | C4: Informação
B5: Escritório: DIAS COSTA SOCIEDADE DE ADVOGADOS | E5: =COUNTA(Tabela1[ID do Caso]) -> 0
B6: CNPJ: 10.999.280/0001-47
B7: Data da Solicitação:
B8: Nº Nota ou Recibo:
B9: N° planilha de pagamentos do PANJUD
B10: Tipo: | C10: Reembolso
B11: R$ Total (Pré-validado): R$
B12: R$ Total (Não contabilizado): | C12: =SUMIF(Tabela1[Validação],">"&0,Tabela1[R$ Valor]) -> 0
B14: Correções necessárias!
B16: =IF(COUNTIF(Tabela1[Campos Não Preenchidos],">"&0)>0,"1. Existem registros incompletos que não serão considerados para análise.","")
B17: =IF(COUNTIF(Tabela1[Range de Pagamento],">"&0)>0,"2. Existem registros fora do prazo de reembolso.","")
B18: =IF(COUNTIF(Tabela1[Duplicidade na solicitação],">"&0)>0,"3. Existem registros duplicados nessa solicitação.","")
B20: =SUM(Tabela1[Validação]) -> 0
